<mujoco model="franka_panda v200">
<!-- =================================================
    Copyright 2018 Vikash Kumar
    Model   :: Franka (MuJoCoV2.0)
    Author  :: Vikash Kumar (vikashplus@gmail.com)
    source  :: https://github.com/vikashplus/franka_sim
    License :: Under Apache License, Version 2.0 (the "License"); you may not use this file except in compliance with the License. You may obtain a copy of the License at http://www.apache.org/licenses/LICENSE-2.0 Unless required by applicable law or agreed to in writing, software distributed under the License is distributed on an "AS IS" BASIS, WITHOUT WARRANTIES OR CONDITIONS OF ANY KIND, either express or implied. See the License for the specific language governing permissions and limitations under the License.
====================================================== -->
    <compiler angle="radian" meshdir=""/>
    <option timestep="0.002"/>
    <size nuser_actuator="5"/>

    <asset>
        <mesh name="link0_col" file="./meshes/collision/link0.stl"/>
        <mesh name="link1_col" file="./meshes/collision/link1.stl"/>
        <mesh name="link2_col" file="./meshes/collision/link2.stl"/>
        <mesh name="link3_col" file="./meshes/collision/link3.stl"/>
        <mesh name="link4_col" file="./meshes/collision/link4.stl"/>
        <mesh name="link5_col" file="./meshes/collision/link5.stl"/>
        <mesh name="link6_col" file="./meshes/collision/link6.stl"/>
        <mesh name="link7_col" file="./meshes/collision/link7.stl"/>
        <mesh name="hand_col" file="./meshes/collision/hand.stl"/>
        <mesh name="link0_viz" file="./meshes/visual/link0.stl"/>
        <mesh name="link1_viz" file="./meshes/visual/link1.stl"/>
        <mesh name="link2_viz" file="./meshes/visual/link2.stl"/>
        <mesh name="link3_viz" file="./meshes/visual/link3.stl"/>
        <mesh name="link3_dark_viz" file="./meshes/visual/link3_dark.stl" scale="1.01 1.01 1.01"/>
        <mesh name="link4_viz" file="./meshes/visual/link4.stl"/>
        <mesh name="link4_dark_viz" file="./meshes/visual/link4_dark.stl" scale="1.01 1.01 1.01"/>
        <mesh name="link5_viz" file="./meshes/visual/link5.stl"/>
        <mesh name="link5_dark_viz" file="./meshes/visual/link5_dark.stl" scale="1.01 1.01 1.01"/>
        <mesh name="link6_viz" file="./meshes/visual/link6.stl"/>
        <mesh name="link6_dark_viz" file="./meshes/visual/link6_dark.stl" scale="1.01 1.01 1.01"/>
        <mesh name="link7_viz" file="./meshes/visual/link7.stl"/>
        <mesh name="link7_dark_viz" file="./meshes/visual/link7_dark.stl" scale="1.01 1.01 1.01"/>
        <mesh name="hand_viz" file="./meshes/visual/hand.stl"/>

        <mesh name="finger_col" file="./meshes/collision/finger.stl" scale='1.75 1.0 1.75'/>
        <mesh name="finger_viz" file="./meshes/collision/finger.stl" scale='1.75 1.0 1.75'/>
    </asset>

    <default>
        <default class="panda">
            <joint pos="0 0 0" axis="0 0 1" limited="true"/>
            <position forcelimited="true" ctrllimited="true" user="1002 40 2001 -0.005 0.005"/>
            <default class="panda_viz">
                <geom contype="0" conaffinity="0" group="0" type="mesh" rgba=".92 .92 .95 1" mass="0"/>
            </default>
            <default class="panda_grey_viz">
                <geom contype="0" conaffinity="0" group="0" type="mesh" rgba=".4 .4 .4 1" mass="0"/>
            </default>

            <default class="panda_col">
                <geom contype="1" conaffinity="1" group="3" type="mesh" rgba=".5 .6 .7 1"/>
            </default>
            <default class="panda_arm">
                <joint damping="100"/>
            </default>
             <default class="panda_forearm">
                <joint damping="10"/>
            </default>
             <default class="panda_finger">
                <joint damping="100" armature='5'/>
                <geom friction="1 0.5 0.0001" solref="0.01 1" solimp="0.8 0.9 0.001" margin="0.001" user="0" rgba="0.5 0.6 0.7 .4" contype="1" conaffinity="0" condim="6" group="3" />
                <position user="1002 40 2001 -0.0001 0.0001"/>
            </default>
        </default>

        <default class="panda_overlay">
            <joint limited="false" damping="1000" armature="1" frictionloss="10"/>
            <geom contype="0" conaffinity="0" group="2" type="mesh" rgba=".42 0.42 0.42 .5"/>
        </default>
    </default>

    <sensor>
        <jointpos name="fr_arm_jp1" joint="panda0_joint1"/>
        <jointpos name="fr_arm_jp2" joint="panda0_joint2"/>
        <jointpos name="fr_arm_jp3" joint="panda0_joint3"/>
        <jointpos name="fr_arm_jp4" joint="panda0_joint4"/>
        <jointpos name="fr_arm_jp5" joint="panda0_joint5"/>
        <jointpos name="fr_arm_jp6" joint="panda0_joint6"/>
        <jointpos name="fr_arm_jp7" joint="panda0_joint7"/>
        <jointvel name="fr_arm_jv1" joint="panda0_joint1"/>
        <jointvel name="fr_arm_jv2" joint="panda0_joint2"/>
        <jointvel name="fr_arm_jv3" joint="panda0_joint3"/>
        <jointvel name="fr_arm_jv4" joint="panda0_joint4"/>
        <jointvel name="fr_arm_jv5" joint="panda0_joint5"/>
        <jointvel name="fr_arm_jv6" joint="panda0_joint6"/>
        <jointvel name="fr_arm_jv7" joint="panda0_joint7"/>

        <jointpos name="fr_fin_jp1" joint="panda0_finger_joint1"/>
        <jointpos name="fr_fin_jp2" joint="panda0_finger_joint2"/>
        <jointvel name="fr_fin_jv1" joint="panda0_finger_joint1"/>
        <jointvel name="fr_fin_jv2" joint="panda0_finger_joint2"/>
    </sensor>
    <!-- <include file="assets/basic_scene.xml"/>
    <include file="assets/assets.xml"/>
    <include file="assets/gripper_assets.xml"/> -->
    

    <worldbody>
        <body name="panda0_link0" childclass="panda" >
            <geom class="panda_viz" mesh="link0_viz"/>
            <geom class="panda_col" mesh="link0_col" mass="2.91242"/>
            <body name="panda0_link1" pos="0 0 0.333">
                <joint name="panda0_joint1" range="-2.8973 2.8973" class="panda_arm"/>
                <geom class="panda_viz" mesh="link1_viz"/>
                <geom class="panda_col" mesh="link1_col" mass="2.7063"/>
                <body name="panda0_link2" pos="0 0 0" quat="0.707107 -0.707107 0 0">
                    <joint name="panda0_joint2" range="-1.7628 1.7628" class="panda_arm"/>
                    <geom class="panda_viz" mesh="link2_viz"/>
                    <geom class="panda_col" mesh="link2_col" mass="2.73046"/>
                    <body name="panda0_link3" pos="0 -0.316 0" quat="0.707107 0.707107 0 0">
                        <joint name="panda0_joint3" range="-2.8973 2.8973" class="panda_arm"/>
                        <geom class="panda_viz" mesh="link3_viz"/>
                        <geom class="panda_grey_viz" mesh="link3_viz" pos="0 .001 0"/>
                        <geom class="panda_col" mesh="link3_col" mass="2.04104"/>
                        <body name="panda0_link4" pos="0.0825 0 0" quat="0.707107 0.707107 0 0">
                            <joint name="panda0_joint4" range="-3.0718 -0.4" class="panda_arm"/>
                            <geom class="panda_viz" mesh="link4_viz"/>
                            <geom class="panda_grey_viz" mesh="link4_viz"/>
                            <geom class="panda_col" mesh="link4_col" mass="2.08129"/>
                            <body name="panda0_link5" pos="-0.0825 0.384 0" quat="0.707107 -0.707107 0 0">
                                <joint name="panda0_joint5" range="-2.8973 2.8973" class="panda_forearm"/>
                                <geom class="panda_viz" mesh="link5_viz"/>
                                <geom class="panda_grey_viz" mesh="link5_viz"/>
                                <geom class="panda_col" mesh="link5_col" mass="3.00049"/>
                                <body name="panda0_link6" pos="0 0 0" euler='1.57 0 1.57'>
                                    <joint name="panda0_joint6" range="-1.6573 2.1127" class="panda_forearm"/>
                                    <!-- <body name="panda0_link6" pos="0 0 0" quat="0.707107 0.707107 0 0"> -->
                                    <!-- <joint name="panda0_joint6" range="-0.0873 3.8223" class="panda_forearm"/> -->
                                    <geom class="panda_viz" mesh="link6_viz"/>
                                    <geom class="panda_grey_viz" mesh="link6_viz"/>
                                    <geom class="panda_col" mesh="link6_col" mass="1.3235"/>
                                    <body name="panda0_link7" pos="0.088 0 0" euler='1.57 0 0.7854'>
                                        <joint name="panda0_joint7" range="-2.8973 2.8973" class="panda_forearm"/>
                                        <!-- <body name="panda0_link7" pos="0.088 0 0" quat="0.707107 0.707107 0 0"> -->
                                        <!-- <joint name="panda0_joint7" range="-2.9671 2.9671" class="panda_forearm"/> -->
                                        <geom class="panda_viz" mesh="link7_viz" rgba=".8 .8 .82 1"/>
                                        <geom class="panda_grey_viz" mesh="link7_viz" pos="0 0 -.0008"/>
                                        <geom class="panda_col" mesh="link7_col" mass="0.2"/>

                                        <!-- End Effector -->
                                        <body name="panda0_gripper">
                                            <geom pos="0 0 0.107" quat="0.92388 0 0 -0.382683" class="panda_viz" mesh="hand_viz"/>
                                            <geom pos="0 0 0.107" quat="0.92388 0 0 -0.382683" class="panda_col" mesh="hand_col" mass="0.81909"/>
                                            <site name='end_effector' pos='0 0 .210' size='0.01' euler='0 0 -0.785398'/>

                                            <body name="panda0_leftfinger" pos="0 0 0.1654" quat="0.92388 0 0 -0.382683" childclass='panda_finger'>
                                                <inertial pos="-1.57863e-05 0.0118731 0.0434103" quat="0.705868 0.0310348 -0.0314925 0.706962" mass="0.0927059" diaginertia="6.57134e-05 6.09611e-05 1.09932e-05" />
                                                <joint name="panda0_finger_joint1"  axis="0 1 0" type="slide" range="0 0.04" class="panda_finger"/>
                                                <geom class="panda_viz" mesh="finger_viz"/>
                                                <!-- <geom class="panda_col" mesh="finger_col"/> -->
                                                <geom size="0.0070" fromto=".009 .006 .0875   -.009 .009 .0875" type="capsule" />
                                                <geom size="0.0070" fromto=".009 .009 .0875   -.009 .006 .0875" type="capsule" />

                                                <geom size="0.0075" fromto=".009 .007 .0775   -.009 .010 .0775" type="capsule" />
                                                <geom size="0.0075" fromto=".009 .010 .0775   -.009 .007 .0775" type="capsule" />

                                                <geom size="0.0082" fromto=".009 .008 .0675   -.009 .011 .0675" type="capsule" />
                                                <geom size="0.0082" fromto=".009 .011 .0675   -.009 .008 .0675" type="capsule" />

                                                <geom size="0.0090" fromto=".009 .009 .0575   -.009 .012 .0575" type="capsule" />
                                                <geom size="0.0090" fromto=".009 .012 .0575   -.009 .009 .0575" type="capsule" />

                                                <geom size="0.0100" fromto=".009 .0105 .0475   -.009 .0135 .0475" type="capsule" />
                                                <geom size="0.0100" fromto=".009 .0135 .0475   -.009 .0105 .0475" type="capsule" />

                                                <geom size="0.0110" fromto=".009 .012 .035   -.009 .015 .035" type="capsule" />
                                                <geom size="0.0110" fromto=".009 .015 .035   -.009 .012 .035" type="capsule" />

                                                <geom size="0.0185 0.0120 0.0175" pos="0 0.014 0.015" type="box" euler='.03 0 0' />

                                            </body>
                                            <body name="panda0_rightfinger" pos="0 0 0.1654" quat="0.92388 0 0 -0.382683"  childclass='panda_finger'>
                                                <inertial pos="1.57863e-05 -0.0118731 0.0434103" quat="0.705868 -0.0310348 0.0314925 0.706962" mass="0.0927059" diaginertia="6.57134e-05 6.09611e-05 1.09932e-05" />
                                                <joint name="panda0_finger_joint2" axis="0 -1 0" type="slide" range="0 0.04" class="panda_finger"/>
                                                <geom quat="0 0 0 1" class="panda_viz" mesh="finger_viz"/>
                                                <!-- <geom class="panda_col" mesh="finger_col"/> -->
                                                <geom size="0.0070" fromto=".009 -.006 .0875   -.009 -.009 .0875" type="capsule" />
                                                <geom size="0.0070" fromto=".009 -.009 .0875   -.009 -.006 .0875" type="capsule" />

                                                <geom size="0.0075" fromto=".009 -.007 .0775   -.009 -.010 .0775" type="capsule" />
                                                <geom size="0.0075" fromto=".009 -.010 .0775   -.009 -.007 .0775" type="capsule" />

                                                <geom size="0.0082" fromto=".009 -.008 .0675   -.009 -.011 .0675" type="capsule" />
                                                <geom size="0.0082" fromto=".009 -.011 .0675   -.009 -.008 .0675" type="capsule" />

                                                <geom size="0.0090" fromto=".009 -.009 .0575   -.009 -.012 .0575" type="capsule" />
                                                <geom size="0.0090" fromto=".009 -.012 .0575   -.009 -.009 .0575" type="capsule" />

                                                <geom size="0.0100" fromto=".009 -.0105 .0475   -.009 -.0135 .0475" type="capsule" />
                                                <geom size="0.0100" fromto=".009 -.0135 .0475   -.009 -.0105 .0475" type="capsule" />

                                                <geom size="0.0110" fromto=".009 -.012 .035   -.009 -.015 .035" type="capsule" />
                                                <geom size="0.0110" fromto=".009 -.015 .035   -.009 -.012 .035" type="capsule" />

                                                <geom size="0.0185 0.0120 0.0175" pos="0 -.014 0.015" type="box" euler='-.03 0 0' />
                                            </body>
                                        </body>

                                    </body>
                                </body>
                            </body>
                        </body>
                    </body>
                </body>
            </body>
        </body>
    </worldbody>

    <actuator>
        <position name="panda0_joint1" joint="panda0_joint1" class="panda" kp="870" forcerange="-87 87" ctrlrange="-2.9671 2.9671"/> <!-- velocity="2.1750" -->
        <position name="panda0_joint2" joint="panda0_joint2" class="panda" kp="870" forcerange="-87 87" ctrlrange="-1.8326 1.8326"/> <!-- velocity="2.1750" -->
        <position name="panda0_joint3" joint="panda0_joint3" class="panda" kp="870" forcerange="-87 87" ctrlrange="-2.9671 2.9671"/> <!-- velocity="2.1750" -->
        <position name="panda0_joint4" joint="panda0_joint4" class="panda" kp="870" forcerange="-87 87" ctrlrange="-3.1416 0.0"/> <!-- velocity="2.1750" -->
        <position name="panda0_joint5" joint="panda0_joint5" class="panda" kp="120" forcerange="-12 12" ctrlrange="-2.9671 2.9671"/> <!-- velocity="2.6100" -->
        <position name="panda0_joint6" joint="panda0_joint6" class="panda" kp="120" forcerange="-12 12" ctrlrange="-1.66 2.1817"/> <!-- velocity="2.6100" -->
        <position name="panda0_joint7" joint="panda0_joint7" class="panda" kp="120" forcerange="-12 12" ctrlrange="-2.9671 2.9671"/> <!-- velocity="2.9671" -->
    </actuator>
    <!-- <include file='assets/actuator0.xml'/> -->

</mujoco>
