<mujoco model="microwave">
    <compiler inertiafromgeom="auto" inertiagrouprange="4 4" angle="radian"/>
    <!-- <include file='../scenes/basic_scene.xml'/>
    <include file="./assets/microwave_asset.xml"/> -->
    <asset>
        <mesh file="./meshes/micro.stl" name="micro"/>
        <mesh file="./meshes/microdoor.stl" name="microdoor"/>
        <mesh file="./meshes/microbutton.stl" name="microbutton"/>
        <mesh file="./meshes/microfeet.stl" name="microfeet"/>
        <mesh file="./meshes/microhandle.stl" name="microhandle"/>
        <mesh file="./meshes/microwindow.stl" name="microwindow"/>
        <mesh file='./meshes/microhandle_l.stl' name='microhandle_l'/>
        <mesh file='./meshes/microhandle_s.stl' name='microhandle_s'/>

        <texture name="T_micro_metal" type="cube" height="1" width="1" file="./textures/metal1.png"/>

        <material name="micro_metal" rgba="1 1 1 1" texture="T_micro_metal" texrepeat="3 3" reflectance="1" shininess="1" texuniform="false"/>
        <material name="micro_black" rgba=".2 .2 .2 1" reflectance="1" shininess="1"/>
        <material name="micro_window" rgba=".4 .4 .4 .25" reflectance="1" shininess="1"/>
        <material name="micro_collision_blue" rgba="0.3 0.3 1.0 0.5" shininess="0" specular="0"/>
    </asset>

    <default>
        <default class="microwave">
            <joint damping="2" frictionloss="2" armature=".01" limited="true"/>
            <geom conaffinity="0" contype="0" group="1" material="micro_black" type="mesh"/>
            <default class="micro_collision">
                <geom conaffinity="1" condim="3" contype="0" group="4" margin="0.001" material="micro_collision_blue" solimp=".8 .9 .01" solref=".02 1"/>
            </default>
        </default>
    </default>


    <worldbody>

        <body name="microroot" childclass="microwave">
            <geom mesh="micro"/>
            <geom material="micro_metal" mesh="microbutton"/>
            <geom material="micro_metal" mesh="microfeet"/>

            <geom class="micro_collision" pos="-0.316 0.023 0.187" size="0.029 0.199 0.187" type="box" mass=".5"/>
            <geom class="micro_collision" pos="0.236 0.023 0.187" size="0.109 0.199 0.187" type="box" mass=".5"/>
            <geom class="micro_collision" pos="-0.081 0.191 0.187" size="0.207 0.03 0.187" type="box" mass=".5"/>
            <geom class="micro_collision" pos="-0.08 -0.007 0.355" size="0.207 0.169 0.019" type="box" mass=".5"/>
            <geom class="micro_collision" pos="-0.08 -0.008 0.024" size="0.207 0.168 0.024" type="box" mass=".5"/>
            <geom class="micro_collision" pos="0.26 -0.197 0.187" size="0.085 0.024 0.187" type="box" mass=".5"/>
            
            <body name="microdoorroot" pos="-0.345 -0.176 0.192">
                <joint axis="0 0 1" limited="true" name="microjoint" range="-2.094 0"/>
                
                <geom mesh="microdoor" pos="0.345 0.176 -0.192"/>
                <geom material="micro_window" mesh="microwindow" pos="0.345 0.176 -0.192"/>
                <geom material="micro_metal" pos="0.475 -0.108 0" size="0.02 0.13" mesh="microhandle_l"/>
                <geom material="micro_metal" euler="1.57 0 0" pos="0.475 -0.075 .13" mesh='microhandle_s'/>
                <geom material="micro_metal" euler="1.57 0 0" pos="0.475 -0.075 -.13" mesh='microhandle_s'/> 

                
                <!-- <geom material="micro_metal" fromto="0.0 0.0 0.0 0.2 0.2 0.0" name="aux_1_geom" size="0.08" type="capsule" rgba=".999 .2 .1 1"/> -->
                <!-- <geom material="micro_metal" fromto="0.0 0.0 0.0 0.2 0.2 0.0" pos="0.475 -0.075 .13" size="0.02 0.03" type="capsule"/>
                <geom material="micro_metal" fromto="0.0 0.0 0.0 0.2 0.2 0.0" pos="0.475 -0.075 -.13" size="0.02 0.03" type="capsule"/> -->

                <geom class="micro_collision" pos="0.475 -0.108 0" size="0.02 0.13" type="capsule" mass="0.020"/>
                <geom class="micro_collision" euler="1.57 0 0" pos="0.475 -0.075 .13" size="0.02 0.03" type="capsule" mass="0.020"/>
                <geom class="micro_collision" euler="1.57 0 0" pos="0.475 -0.075 -.13" size="0.02 0.03" type="capsule" mass="0.020"/>
                <geom class="micro_collision" pos="0.259 -0.026 0" size="0.259 0.024 0.185" type="box" mass="0.20"/>
                <site type="sphere" name="microhandle_site" pos="0.475 -0.108 0" size=".01" group="3" rgba="1 1 0 1"/>
            </body>
            
        </body>

    </worldbody>

</mujoco>
