<?xml version="1.0"?>
<robot name="blue_button">
    <link name="robot_base">
        <visual name="push_buttons_target2">
            <origin xyz="0 0 0.010500" rpy="-3.141593 3.141593 -3.141593" />
            <geometry>
                <box size="0.100000 0.100000 0.021000" />
            </geometry>
            <material name="robot_base_material">
                <color rgba="0.000000 0.500000 1.000000 1.0" />
            </material>
        </visual>
    </link>
    <joint type="prismatic" name="blue_joint">
        <axis xyz="0 0 1" />
        <limit velocity="10.0" upper="0.002" effort="250.0" lower="-0.008" />
        <parent link="robot_base" />
        <child link="blue_top" />
        <origin xyz="0 0 -0.010519" rpy="-3.141593 3.141593 -3.141593" />
    </joint>
    <link name="blue_top">
        <inertial>
            <origin rpy="-3.141593 3.141593 -3.141593" xyz="0.000000 0.000000 0.037950" />
            <inertia ixx="1.3361750093067e-05" ixy="-1.7668542498804e-21" izz="2.6688580837659e-05" iyz="-1.9742168545736e-13" iyy="1.3361752087318e-05" ixz="9.9680512074237e-14" />
            <mass value="0.068521969020367" />
        </inertial>
        <collision name="target_button_topPlate2">
            <origin xyz="0.000000 0.000000 0.037950" rpy="-3.141593 3.141593 -3.141593" />
            <geometry>
                <cylinder radius="0.028000000864267" length="0.0017499999376014" />
            </geometry>
        </collision>
        <visual name="target_button_topPlate2">
            <origin xyz="0.000000 0.000000 0.037950" rpy="-3.141593 3.141593 -3.141593" />
            <geometry>
                <cylinder radius="0.028000000864267" length="0.0017499999376014" />
            </geometry>
            <material name="target_button_topPlate2_material">
                <color rgba="1.000000 0.000000 0.000000 1.0" />
            </material>
        </visual>
        <visual name="target_button_wrap2">
            <origin xyz="0.000000 0.000000 0.034919" rpy="-3.141593 3.141593 -3.141593" />
            <geometry>
                <cylinder radius="0.028000000864267" length="0.0099999997764826" />
            </geometry>
            <material name="target_button_wrap2_material">
                <color rgba="1.000000 0.000000 0.000000 1.0" />
            </material>
        </visual>
    </link>
</robot>