<?xml version="1.0"?>
<robot name="yellow_button">
    <link name="robot_base">
        <visual name="push_buttons_target1">
            <origin xyz="0 0 0.010500" rpy="-3.141593 3.141593 -3.141593" />
            <geometry>
                <box size="0.100000 0.100000 0.021000" />
            </geometry>
            <material name="robot_base_material">
                <color rgba="1 0.5 0 1.0" />
            </material>
        </visual>
    </link>
    <joint name="yellow_joint" type="prismatic">
        <axis xyz="0 0 1" />
        <limit velocity="10.0" upper="0.002" effort="250.0" lower="-0.008" />
        <parent link="robot_base" />
        <child link="yellow_top" />
        <origin xyz="0.0 0.0 -0.010519" rpy="-3.141593 3.141593 -3.141593" />
    </joint>
    <link name="yellow_top">
        <inertial>
            <origin xyz="0.000000 0.000000 0.037950" rpy="-3.141593 3.141593 -3.141593" />
            <inertia izz="2.6688580837659e-05" iyy="1.3361752087318e-05" ixx="1.3361750093067e-05" ixy="-1.7668542498804e-21" ixz="9.9680512074237e-14" iyz="-1.9742168545736e-13" />
            <mass value="0.068521969020367" />
        </inertial>
        <collision name="target_button_topPlate1">
            <origin xyz="0.000000 0.000000 0.037950" rpy="-3.141593 3.141593 -3.141593" />
            <geometry>
                <cylinder radius="0.028000000864267" length="0.0017499999376014" />
            </geometry>
        </collision>
        <visual name="target_button_topPlate1">
            <origin xyz="0.000000 0.000000 0.037950" rpy="-3.141593 3.141593 -3.141593" />
            <geometry>
                <cylinder radius="0.028000000864267" length="0.0017499999376014" />
            </geometry>
            <material name="target_button_topPlate1_material">
                <color rgba="1.000000 0.000000 0.000000 1.0" />
            </material>
        </visual>
        <visual name="target_button_wrap1">
            <origin xyz="0.000000 0.000000 0.034919" rpy="-3.141593 3.141593 -3.141593" />
            <geometry>
                <cylinder radius="0.028000000864267" length="0.0099999997764826" />
            </geometry>
            <material name="target_button_wrap1_material">
                <color rgba="1.000000 0.000000 0.000000 1.0" />
            </material>
        </visual>
    </link>
</robot>
